Error 2021-02-16 12:14:08: Exception while attempting zmq : [Error: /snap/core/current/usr/lib/x86_64-linux-gnu/libstdc++.so.6: version `GLIBCXX_3.4.22' not found (required by /home/tsubase/.vscode/extensions/ms-toolsai.jupyter-2020.12.414227025/out/client/node_modules/zeromq/prebuilds/linux-x64/electron.napi.glibc.node)
	at process.func [as dlopen] (electron/js2c/asar_bundle.js:5:1812)
	at Object.Module._extensions..node (internal/modules/cjs/loader.js:1250:18)
	at Object.func [as .node] (electron/js2c/asar_bundle.js:5:1812)
	at Module.load (internal/modules/cjs/loader.js:1039:32)
	at Module._load (internal/modules/cjs/loader.js:932:14)
	at Function.f._load (electron/js2c/asar_bundle.js:5:12738)
	at Function.o._load (/snap/code/55/usr/share/code/resources/app/out/vs/workbench/services/extensions/node/extensionHostProcess.js:104:27152)
	at Function.p._load (/snap/code/55/usr/share/code/resources/app/out/vs/workbench/services/extensions/node/extensionHostProcess.js:104:23904)
	at Function.M._load (/snap/code/55/usr/share/code/resources/app/out/vs/workbench/services/extensions/node/extensionHostProcess.js:94:62159)
	at Module.require (internal/modules/cjs/loader.js:1079:19)
	at v (/snap/code/55/usr/share/code/resources/app/out/vs/loader.js:3:12287)
	at load (/home/tsubase/.vscode/extensions/ms-toolsai.jupyter-2020.12.414227025/out/client/node_modules/node-gyp-build/index.js:21:10)
	at Object.<anonymous> (/home/tsubase/.vscode/extensions/ms-toolsai.jupyter-2020.12.414227025/out/client/node_modules/zeromq/lib/native.js:6:43)
	at Module.u._compile (/snap/code/55/usr/share/code/resources/app/out/vs/loader.js:3:12841)
	at Object.Module._extensions..js (internal/modules/cjs/loader.js:1220:10)
	at Module.load (internal/modules/cjs/loader.js:1039:32)
	at Module._load (internal/modules/cjs/loader.js:932:14)
	at Function.f._load (electron/js2c/asar_bundle.js:5:12738)
	at Function.o._load (/snap/code/55/usr/share/code/resources/app/out/vs/workbench/services/extensions/node/extensionHostProcess.js:104:27152)
	at Function.p._load (/snap/code/55/usr/share/code/resources/app/out/vs/workbench/services/extensions/node/extensionHostProcess.js:104:23904)
	at Function.M._load (/snap/code/55/usr/share/code/resources/app/out/vs/workbench/services/extensions/node/extensionHostProcess.js:94:62159)
	at Module.require (internal/modules/cjs/loader.js:1079:19)
	at v (/snap/code/55/usr/share/code/resources/app/out/vs/loader.js:3:12287)
	at Object.<anonymous> (/home/tsubase/.vscode/extensions/ms-toolsai.jupyter-2020.12.414227025/out/client/node_modules/zeromq/lib/index.js:3:16)
	at Module.u._compile (/snap/code/55/usr/share/code/resources/app/out/vs/loader.js:3:12841)
	at Object.Module._extensions..js (internal/modules/cjs/loader.js:1220:10)
	at Module.load (internal/modules/cjs/loader.js:1039:32)
	at Module._load (internal/modules/cjs/loader.js:932:14)
	at Function.f._load (electron/js2c/asar_bundle.js:5:12738)
	at Function.o._load (/snap/code/55/usr/share/code/resources/app/out/vs/workbench/services/extensions/node/extensionHostProcess.js:104:27152)
	at Function.p._load (/snap/code/55/usr/share/code/resources/app/out/vs/workbench/services/extensions/node/extensionHostProcess.js:104:23904)
	at Function.M._load (/snap/code/55/usr/share/code/resources/app/out/vs/workbench/services/extensions/node/extensionHostProcess.js:94:62159)
	at Module.require (internal/modules/cjs/loader.js:1079:19)
	at v (/snap/code/55/usr/share/code/resources/app/out/vs/loader.js:3:12287)
	at Object.<anonymous> (/home/tsubase/.vscode/extensions/ms-toolsai.jupyter-2020.12.414227025/out/client/extension.js:32:274679)
	at n (/home/tsubase/.vscode/extensions/ms-toolsai.jupyter-2020.12.414227025/out/client/extension.js:1:186)
	at /home/tsubase/.vscode/extensions/ms-toolsai.jupyter-2020.12.414227025/out/client/extension.js:49:803883
	at processTicksAndRejections (internal/process/task_queues.js:97:5)
	at async u.zmqSupportedImpl (/home/tsubase/.vscode/extensions/ms-toolsai.jupyter-2020.12.414227025/out/client/extension.js:49:803850)]
Error 2021-02-16 12:14:08: Jupyter Extension (Error in Failed to update settings.json, method:fixSettingsFile): [EntryNotFound (FileSystemError): Unable to read file '/home/tsubase/pythonProjects/.vscode/settings.json' (Error: Unable to resolve non-existing file '/home/tsubase/pythonProjects/.vscode/settings.json')
	at _handleError (/snap/code/55/usr/share/code/resources/app/out/vs/workbench/services/extensions/node/extensionHostProcess.js:86:136165)
	at processTicksAndRejections (internal/process/task_queues.js:97:5)
	at async m.readFile (/home/tsubase/.vscode/extensions/ms-toolsai.jupyter-2020.12.414227025/out/client/extension.js:49:832552)
	at async g.fixSettingsFile (/home/tsubase/.vscode/extensions/ms-toolsai.jupyter-2020.12.414227025/out/client/extension.js:47:288845)
	at async Promise.all (index 1)
	at async g.updateSettings (/home/tsubase/.vscode/extensions/ms-toolsai.jupyter-2020.12.414227025/out/client/extension.js:47:290565)] {
  code: 'FileNotFound'
}
> /usr/bin/python3 ~/.vscode/extensions/ms-toolsai.jupyter-2020.12.414227025/pythonFiles/pyvsc-run-isolated.py -c "import jupyter"
> /usr/bin/python3 ~/.vscode/extensions/ms-toolsai.jupyter-2020.12.414227025/pythonFiles/pyvsc-run-isolated.py -c "import jupyter"
> /usr/bin/python3 ~/.vscode/extensions/ms-toolsai.jupyter-2020.12.414227025/pythonFiles/pyvsc-run-isolated.py -c "import notebook"
> /usr/bin/python3 ~/.vscode/extensions/ms-toolsai.jupyter-2020.12.414227025/pythonFiles/pyvsc-run-isolated.py -c "import notebook"
> /usr/bin/python3 ~/.vscode/extensions/ms-toolsai.jupyter-2020.12.414227025/pythonFiles/pyvsc-run-isolated.py jupyter kernelspec --version
> /usr/bin/python3 ~/.vscode/extensions/ms-toolsai.jupyter-2020.12.414227025/pythonFiles/pyvsc-run-isolated.py jupyter kernelspec --version
Error 2021-02-16 12:14:21: Exception attempting to start notebook:  [i [Error]: Jupyter cannot be started. Error attempting to locate jupyter: 
	at w.startServer (/home/tsubase/.vscode/extensions/ms-toolsai.jupyter-2020.12.414227025/out/client/extension.js:49:379970)
	at runMicrotasks (<anonymous>)
	at processTicksAndRejections (internal/process/task_queues.js:97:5)
	at async w.createServer (/home/tsubase/.vscode/extensions/ms-toolsai.jupyter-2020.12.414227025/out/client/extension.js:49:379268)
	at async connect (/home/tsubase/.vscode/extensions/ms-toolsai.jupyter-2020.12.414227025/out/client/extension.js:49:504021)
	at async f.ensureConnectionAndNotebookImpl (/home/tsubase/.vscode/extensions/ms-toolsai.jupyter-2020.12.414227025/out/client/extension.js:32:590192)
	at async f.ensureConnectionAndNotebook (/home/tsubase/.vscode/extensions/ms-toolsai.jupyter-2020.12.414227025/out/client/extension.js:32:588656)
	at async f.clearResult (/home/tsubase/.vscode/extensions/ms-toolsai.jupyter-2020.12.414227025/out/client/extension.js:32:584410)
	at async f.reexecuteCell (/home/tsubase/.vscode/extensions/ms-toolsai.jupyter-2020.12.414227025/out/client/extension.js:9:171119)
	at async f.reexecuteCells (/home/tsubase/.vscode/extensions/ms-toolsai.jupyter-2020.12.414227025/out/client/extension.js:9:167423)] {
  action: 'https://aka.ms/pyaiinstall',
  actionTitle: 'Get more help'
}
Error 2021-02-16 12:14:21: DataScience Error [i [Error]: Jupyter cannot be started. Error attempting to locate jupyter: 
	at w.startServer (/home/tsubase/.vscode/extensions/ms-toolsai.jupyter-2020.12.414227025/out/client/extension.js:49:379970)
	at runMicrotasks (<anonymous>)
	at processTicksAndRejections (internal/process/task_queues.js:97:5)
	at async w.createServer (/home/tsubase/.vscode/extensions/ms-toolsai.jupyter-2020.12.414227025/out/client/extension.js:49:379268)
	at async connect (/home/tsubase/.vscode/extensions/ms-toolsai.jupyter-2020.12.414227025/out/client/extension.js:49:504021)
	at async f.ensureConnectionAndNotebookImpl (/home/tsubase/.vscode/extensions/ms-toolsai.jupyter-2020.12.414227025/out/client/extension.js:32:590192)
	at async f.ensureConnectionAndNotebook (/home/tsubase/.vscode/extensions/ms-toolsai.jupyter-2020.12.414227025/out/client/extension.js:32:588656)
	at async f.clearResult (/home/tsubase/.vscode/extensions/ms-toolsai.jupyter-2020.12.414227025/out/client/extension.js:32:584410)
	at async f.reexecuteCell (/home/tsubase/.vscode/extensions/ms-toolsai.jupyter-2020.12.414227025/out/client/extension.js:9:171119)
	at async f.reexecuteCells (/home/tsubase/.vscode/extensions/ms-toolsai.jupyter-2020.12.414227025/out/client/extension.js:9:167423)] {
  action: 'https://aka.ms/pyaiinstall',
  actionTitle: 'Get more help'
}
> /usr/bin/python3 ~/.vscode/extensions/ms-toolsai.jupyter-2020.12.414227025/pythonFiles/pyvsc-run-isolated.py vscode_datascience_helpers.daemon --daemon-module=vscode_datascience_helpers.jupyter_daemon -v
> /usr/bin/python3 ~/.vscode/extensions/ms-toolsai.jupyter-2020.12.414227025/pythonFiles/pyvsc-run-isolated.py vscode_datascience_helpers.daemon --daemon-module=vscode_datascience_helpers.jupyter_daemon -v
> /usr/bin/python3 ~/.vscode/extensions/ms-toolsai.jupyter-2020.12.414227025/pythonFiles/pyvsc-run-isolated.py vscode_datascience_helpers.daemon --daemon-module=vscode_datascience_helpers.jupyter_daemon -v
> /usr/bin/python3 ~/.vscode/extensions/ms-toolsai.jupyter-2020.12.414227025/pythonFiles/pyvsc-run-isolated.py vscode_datascience_helpers.daemon --daemon-module=vscode_datascience_helpers.jupyter_daemon -v
> /usr/bin/python3 ~/.vscode/extensions/ms-toolsai.jupyter-2020.12.414227025/pythonFiles/pyvsc-run-isolated.py vscode_datascience_helpers.daemon --daemon-module=vscode_datascience_helpers.jupyter_daemon -v
> /usr/bin/python3 ~/.vscode/extensions/ms-toolsai.jupyter-2020.12.414227025/pythonFiles/pyvsc-run-isolated.py vscode_datascience_helpers.daemon --daemon-module=vscode_datascience_helpers.jupyter_daemon -v
> /usr/bin/python3 (daemon) -m jupyter kernelspec list --json
> /usr/bin/python3 (daemon) -m jupyter kernelspec list --json
Starting Jupyter from /usr/bin/python3 with command line --no-browser --notebook-dir="/home/tsubase/pythonProjects" --config=/tmp/383556bf-64f1-4608-bb91-259e9519dcf8/jupyter_notebook_config.py --NotebookApp.iopub_data_rate_limit=10000000000.0
> /usr/bin/python3 (daemon) -m jupyter notebook --no-browser --notebook-dir="/home/tsubase/pythonProjects" --config=/tmp/383556bf-64f1-4608-bb91-259e9519dcf8/jupyter_notebook_config.py --NotebookApp.iopub_data_rate_limit=10000000000.0
> /usr/bin/python3 (daemon) ~/.vscode/extensions/ms-toolsai.jupyter-2020.12.414227025/pythonFiles/vscode_datascience_helpers/getJupyterKernels.py
> /usr/bin/python3 (daemon) ~/.vscode/extensions/ms-toolsai.jupyter-2020.12.414227025/pythonFiles/vscode_datascience_helpers/getJupyterKernels.py
[I 12:14:28.086 NotebookApp] Serving notebooks from local directory: /home/tsubase/pythonProjects
[I 12:14:28.086 NotebookApp] The Jupyter Notebook is running at:
[I 12:14:28.086 NotebookApp] http://localhost:8888/?token=02211b759e8dd8ba986a142dc097a8812bd74788220bd2b3
> /usr/bin/python3 (daemon) ~/.vscode/extensions/ms-toolsai.jupyter-2020.12.414227025/pythonFiles/vscode_datascience_helpers/getServerInfo.py
[I 12:14:28.086 NotebookApp] Use Control-C to stop this server and shut down all kernels (twice to skip confirmation).
> /usr/bin/python3 (daemon) ~/.vscode/extensions/ms-toolsai.jupyter-2020.12.414227025/pythonFiles/vscode_datascience_helpers/getServerInfo.py
[C 12:14:28.087 NotebookApp] 
    
    Copy/paste this URL into your browser when you connect for the first time,
    to login with a token:
        http://localhost:8888/?token=02211b759e8dd8ba986a142dc097a8812bd74788220bd2b3
> /usr/bin/python3 (daemon) ~/.vscode/extensions/ms-toolsai.jupyter-2020.12.414227025/pythonFiles/vscode_datascience_helpers/getServerInfo.py
[I 12:14:28.847 NotebookApp] Creating new notebook in /
[I 12:14:28.905 NotebookApp] Kernel started: 6b9a2944-bfb1-4d9b-b558-37ac9e288074
[W 12:14:28.919 NotebookApp] delete /t-bbd738fa-ed32-4a8c-87e7-7b007cdeb6b8.ipynb
[W 12:14:30.412 NotebookApp] Replacing stale connection: 6b9a2944-bfb1-4d9b-b558-37ac9e288074:40a76dd7-8b6a-452a-8ad3-8753afe14c5b
Error 2021-02-16 12:15:28: Failed to connect to server [r [Error]: The Jupyter notebook server failed to launch in time
	at y.waitForIdleOnSession (/home/tsubase/.vscode/extensions/ms-toolsai.jupyter-2020.12.414227025/out/client/extension.js:1:433870)
	at async y.createNewKernelSession (/home/tsubase/.vscode/extensions/ms-toolsai.jupyter-2020.12.414227025/out/client/extension.js:49:555367)
	at async y.connect (/home/tsubase/.vscode/extensions/ms-toolsai.jupyter-2020.12.414227025/out/client/extension.js:49:554970)
	at async m.startNew (/home/tsubase/.vscode/extensions/ms-toolsai.jupyter-2020.12.414227025/out/client/extension.js:49:550438)
	at async v.connect (/home/tsubase/.vscode/extensions/ms-toolsai.jupyter-2020.12.414227025/out/client/extension.js:49:521987)
	at async /home/tsubase/.vscode/extensions/ms-toolsai.jupyter-2020.12.414227025/out/client/extension.js:32:641509]
> /usr/bin/python3 ~/.vscode/extensions/ms-toolsai.jupyter-2020.12.414227025/pythonFiles/pyvsc-run-isolated.py vscode_datascience_helpers.daemon --daemon-module=vscode_datascience_helpers.jupyter_daemon -v
> /usr/bin/python3 ~/.vscode/extensions/ms-toolsai.jupyter-2020.12.414227025/pythonFiles/pyvsc-run-isolated.py vscode_datascience_helpers.daemon --daemon-module=vscode_datascience_helpers.jupyter_daemon -v
Starting Jupyter from /usr/bin/python3 with command line --no-browser --notebook-dir="/home/tsubase/pythonProjects" --config=/tmp/60be41af-29f4-4e9f-bf7b-752b6c2a8497/jupyter_notebook_config.py --NotebookApp.iopub_data_rate_limit=10000000000.0
> /usr/bin/python3 ~/.vscode/extensions/ms-toolsai.jupyter-2020.12.414227025/pythonFiles/pyvsc-run-isolated.py jupyter notebook --no-browser --notebook-dir="/home/tsubase/pythonProjects" --config=/tmp/60be41af-29f4-4e9f-bf7b-752b6c2a8497/jupyter_notebook_config.py --NotebookApp.iopub_data_rate_limit=10000000000.0
> /usr/bin/python3 ~/.vscode/extensions/ms-toolsai.jupyter-2020.12.414227025/pythonFiles/pyvsc-run-isolated.py jupyter notebook --no-browser --notebook-dir="/home/tsubase/pythonProjects" --config=/tmp/60be41af-29f4-4e9f-bf7b-752b6c2a8497/jupyter_notebook_config.py --NotebookApp.iopub_data_rate_limit=10000000000.0
/home/tsubase/.local/lib/python3.8/site-packages/traitlets/traitlets.py:2195: FutureWarning: Supporting extra quotes around Unicode is deprecated in traitlets 5.0. Use '/home/tsubase/pythonProjects' instead of '"/home/tsubase/pythonProjects"' – or use CUnicode.
  warn(
[I 12:15:29.474 NotebookApp] Serving notebooks from local directory: /home/tsubase/pythonProjects
[I 12:15:29.474 NotebookApp] The Jupyter Notebook is running at:
[I 12:15:29.474 NotebookApp] http://localhost:8888/?token=657f88d43a399a5e73f4de733d038179d23e48746e2c2563
[I 12:15:29.474 NotebookApp] Use Control-C to stop this server and shut down all kernels (twice to skip confirmation).
[C 12:15:29.474 NotebookApp] 
    
    Copy/paste this URL into your browser when you connect for the first time,
    to login with a token:
        http://localhost:8888/?token=657f88d43a399a5e73f4de733d038179d23e48746e2c2563
> /usr/bin/python3 (daemon) ~/.vscode/extensions/ms-toolsai.jupyter-2020.12.414227025/pythonFiles/vscode_datascience_helpers/getServerInfo.py
[I 12:15:29.930 NotebookApp] Creating new notebook in /
[I 12:15:29.975 NotebookApp] Kernel started: f3d39d59-a48c-41dd-94d2-9124068b1592
[W 12:15:29.983 NotebookApp] delete /t-581d37e5-e3b6-47e3-8309-63e4f31d32b5.ipynb
/home/tsubase/.local/lib/python3.8/site-packages/notebook/base/zmqhandlers.py:284: RuntimeWarning: coroutine 'WebSocketHandler.get' was never awaited
  super(AuthenticatedZMQStreamHandler, self).get(*args, **kwargs)
RuntimeWarning: Enable tracemalloc to get the object allocation traceback
[W 12:15:31.343 NotebookApp] Replacing stale connection: f3d39d59-a48c-41dd-94d2-9124068b1592:5ccd0aba-aede-4dfb-aae7-2b6df921cf1b
Error 2021-02-16 12:16:30: Failed to connect to server [r [Error]: The Jupyter notebook server failed to launch in time
	at y.waitForIdleOnSession (/home/tsubase/.vscode/extensions/ms-toolsai.jupyter-2020.12.414227025/out/client/extension.js:1:433870)
	at async y.createNewKernelSession (/home/tsubase/.vscode/extensions/ms-toolsai.jupyter-2020.12.414227025/out/client/extension.js:49:555367)
	at async y.connect (/home/tsubase/.vscode/extensions/ms-toolsai.jupyter-2020.12.414227025/out/client/extension.js:49:554970)
	at async m.startNew (/home/tsubase/.vscode/extensions/ms-toolsai.jupyter-2020.12.414227025/out/client/extension.js:49:550438)
	at async v.connect (/home/tsubase/.vscode/extensions/ms-toolsai.jupyter-2020.12.414227025/out/client/extension.js:49:521987)
	at async /home/tsubase/.vscode/extensions/ms-toolsai.jupyter-2020.12.414227025/out/client/extension.js:32:641509]
[C 12:16:30.016 NotebookApp] received signal 15, stopping
[C 12:16:30.017 NotebookApp] received signal 15, stopping
[I 12:16:30.017 NotebookApp] Shutting down 1 kernel
Starting Jupyter from /usr/bin/python3 with command line --no-browser --notebook-dir="/home/tsubase/pythonProjects" --config=/tmp/a1f5a693-23a2-4fd1-ac08-7d06d07ceaaf/jupyter_notebook_config.py --NotebookApp.iopub_data_rate_limit=10000000000.0
> /usr/bin/python3 (daemon) -m jupyter notebook --no-browser --notebook-dir="/home/tsubase/pythonProjects" --config=/tmp/a1f5a693-23a2-4fd1-ac08-7d06d07ceaaf/jupyter_notebook_config.py --NotebookApp.iopub_data_rate_limit=10000000000.0
[I 12:16:30.319 NotebookApp] Kernel shutdown: f3d39d59-a48c-41dd-94d2-9124068b1592
[I 12:16:30.452 NotebookApp] Serving notebooks from local directory: /home/tsubase/pythonProjects
[I 12:16:30.452 NotebookApp] The Jupyter Notebook is running at:
[I 12:16:30.452 NotebookApp] http://localhost:8888/?token=535b033541ca8c5759d92e9dea3c12eccf591c3624215627
> /usr/bin/python3 (daemon) ~/.vscode/extensions/ms-toolsai.jupyter-2020.12.414227025/pythonFiles/vscode_datascience_helpers/getServerInfo.py
[I 12:16:30.452 NotebookApp] Use Control-C to stop this server and shut down all kernels (twice to skip confirmation).
> /usr/bin/python3 (daemon) ~/.vscode/extensions/ms-toolsai.jupyter-2020.12.414227025/pythonFiles/vscode_datascience_helpers/getServerInfo.py
[C 12:16:30.452 NotebookApp] 
    
    Copy/paste this URL into your browser when you connect for the first time,
    to login with a token:
        http://localhost:8888/?token=535b033541ca8c5759d92e9dea3c12eccf591c3624215627
[I 12:16:30.921 NotebookApp] Creating new notebook in /
> /usr/bin/python3 (daemon) ~/.vscode/extensions/ms-toolsai.jupyter-2020.12.414227025/pythonFiles/vscode_datascience_helpers/getServerInfo.py
[I 12:16:30.985 NotebookApp] Kernel started: 7dee4a4e-4975-4c80-bc16-83bfb3a2abcc
[W 12:16:30.994 NotebookApp] delete /t-8075cdce-26f1-4883-a5bf-715e8ac600a0.ipynb
[W 12:16:32.390 NotebookApp] Replacing stale connection: 7dee4a4e-4975-4c80-bc16-83bfb3a2abcc:de84bbbd-b0d5-4913-923d-0bb81ec0696f
Error 2021-02-16 12:17:31: Failed to connect to server [r [Error]: The Jupyter notebook server failed to launch in time
	at y.waitForIdleOnSession (/home/tsubase/.vscode/extensions/ms-toolsai.jupyter-2020.12.414227025/out/client/extension.js:1:433870)
	at async y.createNewKernelSession (/home/tsubase/.vscode/extensions/ms-toolsai.jupyter-2020.12.414227025/out/client/extension.js:49:555367)
	at async y.connect (/home/tsubase/.vscode/extensions/ms-toolsai.jupyter-2020.12.414227025/out/client/extension.js:49:554970)
	at async m.startNew (/home/tsubase/.vscode/extensions/ms-toolsai.jupyter-2020.12.414227025/out/client/extension.js:49:550438)
	at async v.connect (/home/tsubase/.vscode/extensions/ms-toolsai.jupyter-2020.12.414227025/out/client/extension.js:49:521987)
	at async /home/tsubase/.vscode/extensions/ms-toolsai.jupyter-2020.12.414227025/out/client/extension.js:32:641509]
Error 2021-02-16 12:17:31: Failed to determine if a notebook is active for the current editor [i [Error]: 
	at new i (/home/tsubase/.vscode/extensions/ms-toolsai.jupyter-2020.12.414227025/out/client/extension.js:9:110537)
	at /home/tsubase/.vscode/extensions/ms-toolsai.jupyter-2020.12.414227025/out/client/extension.js:32:642621

Error: The Jupyter notebook server failed to launch in time
	at y.waitForIdleOnSession (/home/tsubase/.vscode/extensions/ms-toolsai.jupyter-2020.12.414227025/out/client/extension.js:1:433870)
	at async y.createNewKernelSession (/home/tsubase/.vscode/extensions/ms-toolsai.jupyter-2020.12.414227025/out/client/extension.js:49:555367)
	at async y.connect (/home/tsubase/.vscode/extensions/ms-toolsai.jupyter-2020.12.414227025/out/client/extension.js:49:554970)
	at async m.startNew (/home/tsubase/.vscode/extensions/ms-toolsai.jupyter-2020.12.414227025/out/client/extension.js:49:550438)
	at async v.connect (/home/tsubase/.vscode/extensions/ms-toolsai.jupyter-2020.12.414227025/out/client/extension.js:49:521987)
	at async /home/tsubase/.vscode/extensions/ms-toolsai.jupyter-2020.12.414227025/out/client/extension.js:32:641509]
Error 2021-02-16 12:17:31: Failed to determine if a notebook is active for the current editor [i [Error]: 
	at new i (/home/tsubase/.vscode/extensions/ms-toolsai.jupyter-2020.12.414227025/out/client/extension.js:9:110537)
	at /home/tsubase/.vscode/extensions/ms-toolsai.jupyter-2020.12.414227025/out/client/extension.js:32:642621

Error: The Jupyter notebook server failed to launch in time
	at y.waitForIdleOnSession (/home/tsubase/.vscode/extensions/ms-toolsai.jupyter-2020.12.414227025/out/client/extension.js:1:433870)
	at async y.createNewKernelSession (/home/tsubase/.vscode/extensions/ms-toolsai.jupyter-2020.12.414227025/out/client/extension.js:49:555367)
	at async y.connect (/home/tsubase/.vscode/extensions/ms-toolsai.jupyter-2020.12.414227025/out/client/extension.js:49:554970)
	at async m.startNew (/home/tsubase/.vscode/extensions/ms-toolsai.jupyter-2020.12.414227025/out/client/extension.js:49:550438)
	at async v.connect (/home/tsubase/.vscode/extensions/ms-toolsai.jupyter-2020.12.414227025/out/client/extension.js:49:521987)
	at async /home/tsubase/.vscode/extensions/ms-toolsai.jupyter-2020.12.414227025/out/client/extension.js:32:641509]
Error 2021-02-16 12:17:31: Exception attempting to start notebook:  [i [Error]: 
	at new i (/home/tsubase/.vscode/extensions/ms-toolsai.jupyter-2020.12.414227025/out/client/extension.js:9:110537)
	at /home/tsubase/.vscode/extensions/ms-toolsai.jupyter-2020.12.414227025/out/client/extension.js:32:642621

Error: The Jupyter notebook server failed to launch in time
	at y.waitForIdleOnSession (/home/tsubase/.vscode/extensions/ms-toolsai.jupyter-2020.12.414227025/out/client/extension.js:1:433870)
	at async y.createNewKernelSession (/home/tsubase/.vscode/extensions/ms-toolsai.jupyter-2020.12.414227025/out/client/extension.js:49:555367)
	at async y.connect (/home/tsubase/.vscode/extensions/ms-toolsai.jupyter-2020.12.414227025/out/client/extension.js:49:554970)
	at async m.startNew (/home/tsubase/.vscode/extensions/ms-toolsai.jupyter-2020.12.414227025/out/client/extension.js:49:550438)
	at async v.connect (/home/tsubase/.vscode/extensions/ms-toolsai.jupyter-2020.12.414227025/out/client/extension.js:49:521987)
	at async /home/tsubase/.vscode/extensions/ms-toolsai.jupyter-2020.12.414227025/out/client/extension.js:32:641509]
Error 2021-02-16 12:17:31: DataScience Error [i [Error]: 
	at new i (/home/tsubase/.vscode/extensions/ms-toolsai.jupyter-2020.12.414227025/out/client/extension.js:9:110537)
	at /home/tsubase/.vscode/extensions/ms-toolsai.jupyter-2020.12.414227025/out/client/extension.js:32:642621

Error: The Jupyter notebook server failed to launch in time
	at y.waitForIdleOnSession (/home/tsubase/.vscode/extensions/ms-toolsai.jupyter-2020.12.414227025/out/client/extension.js:1:433870)
	at async y.createNewKernelSession (/home/tsubase/.vscode/extensions/ms-toolsai.jupyter-2020.12.414227025/out/client/extension.js:49:555367)
	at async y.connect (/home/tsubase/.vscode/extensions/ms-toolsai.jupyter-2020.12.414227025/out/client/extension.js:49:554970)
	at async m.startNew (/home/tsubase/.vscode/extensions/ms-toolsai.jupyter-2020.12.414227025/out/client/extension.js:49:550438)
	at async v.connect (/home/tsubase/.vscode/extensions/ms-toolsai.jupyter-2020.12.414227025/out/client/extension.js:49:521987)
	at async /home/tsubase/.vscode/extensions/ms-toolsai.jupyter-2020.12.414227025/out/client/extension.js:32:641509]
> /usr/bin/python3 ~/.vscode/extensions/ms-toolsai.jupyter-2020.12.414227025/pythonFiles/pyvsc-run-isolated.py vscode_datascience_helpers.daemon --daemon-module=vscode_datascience_helpers.jupyter_daemon -v
> /usr/bin/python3 ~/.vscode/extensions/ms-toolsai.jupyter-2020.12.414227025/pythonFiles/pyvsc-run-isolated.py vscode_datascience_helpers.daemon --daemon-module=vscode_datascience_helpers.jupyter_daemon -v
